Workbook
Name AVP: #REF!
Name bar: [1]PSG!$I$4:$N$23
Name base_case: [2]V!$B$8:$G$19
Name Basic_NOSH: [3]COCKPIT!$I$45
Name BC_Disposal: [3]COCKPIT!$D$102
Name bob_ind_pro: [4]Combined!$B$376:$J$396
Name bobcat_standalone: [4]Combined!$B$334:$J$343
Name BRAZIL_CASE: #REF!
Name BRAZIL_CASE: #REF!
Name broker: [5]Valuation!$L$10:$P$32
Name buyers: [6]PPS!$C$24:$D$29
Name buyin_output: [6]PPS!$B$3:$L$21
Name Call_value: [7]WV!$E$40
Name CapDA: [3]COCKPIT!$D$81
Name CapexSens_Base: [6]DCF!$L$159:$R$165
Name capitalisation: [6]PPS!$I$43:$N$53
Name captax: [3]LBO!$H$26
Name CFS: [6]CFS!$B$9:$H$25
Name choice: [8]Ass!$C$6
Name circ: Assumptions!$D$7
Name ClosePrint: ClosePrint
Name com: [5]FootballField!$D$10:$F$21
Name Comparison_page: [9]Comparison!$B$2:$U$31
Name con: [5]Contribution!$K$4:$R$21
Name Consult_Sales_EBITDA: [4]Consultancy!$B$121:$H$128
Name Consult_WACC_TV: [4]Consultancy!$B$111:$H$118
Name contribution: [6]PPS!$C$132:$F$143
Name credit: [6]LBO!$V$482:$AD$501
Name Current_Price: [3]COCKPIT!$I$33
Name d_1: [7]WV!$E$37
Name d_2: [7]WV!$E$38
Name Days: [3]COCKPIT!$J$16
Name DC_trans_date: '[3]Blue Corning Cluster_COCKPIT'!$E$10
Name DCF: 'DCF input'!$D$22:$T$67
Name DCF_1: 'DCF input'!$F$74:$I$77
Name DCF_2: 'DCF input'!$E$94:$J$99
Name DCF_Date: [3]COCKPIT!$D$72
Name DCF_Stubb: [3]COCKPIT!$D$74
Name DCFoutput: 'DCF output'!$C$7:$T$44
Name DealDate: [10]DEALSheet!$F$11
Name Defence_Sales_EBITDA: '[4]Defence Systems'!$B$121:$H$128
Name Defence_WACC_TV: '[4]Defence Systems'!$B$111:$H$118
Name Diluted_NOSH: [3]COCKPIT!$I$49
Name DML_Multiple_Sensitivity: [4]DCF!$B$126:$H$133
Name DML_WACC_TV: [4]DCF!$B$136:$H$143
Name EBITA_Hist: [6]PPS!$D$161:$X$161,[6]PPS!$D$164:$X$164
Name ebitda: [5]EBIT_SPLIT!$B$6:$P$9,[5]EBIT_SPLIT!$B$48:$P$55,[5]EBIT_SPLIT!$B$68:$P$75,[5]EBIT_SPLIT!$B$88:$P$95,[5]EBIT_SPLIT!$B$108:$P$115,[5]EBIT_SPLIT!$B$128:$P$136,[5]EBIT_SPLIT!$B$139:$P$147
Name edin: '[11]Clubs 1'!$A$1:$N$142
Name eurster: [12]Ved_DealSheet!$F$24
Name ev.Calculation: -4105
Name ev.Initialized: FALSE()
Name Exchange_rate: [13]Input!$D$137:$N$154
Name FCF_Summ: [6]PPS!$C$168:$Q$200
Name fdfg: {"quarterly",#N/A,FALSE,"Income Statement";#N/A,#N/A,FALSE,"print segment";#N/A,#N/A,FALSE,"Balance Sheet";#N/A,#N/A,FALSE,"Annl Inc";#N/A,#N/A,FALSE,"Cash Flow"}
Name fdv: {"quarterly",#N/A,FALSE,"Income Statement";#N/A,#N/A,FALSE,"print segment";#N/A,#N/A,FALSE,"Balance Sheet";#N/A,#N/A,FALSE,"Annl Inc";#N/A,#N/A,FALSE,"Cash Flow"}
Name financials: [13]Financials!$B$8:$FC$847
Name Five_IRR_EBITA: [6]PPS!$AA$60:$AG$68
Name Five_MM: [6]PPS!$AA$74:$AG$82
Name foot: [5]FootballField!$K$10:$M$27
Name FV: [3]COCKPIT!$I$61

Sheet __FDSCACHE__
B1: This sheet contains FactSet XML data for use with this workbook's =FDS codes. Modifying the worksheet's contents may damage the workbook's =FDS functionality.

Sheet Cover sheet
D14: Happy Hour Co — MODEL
C19: S T R I C T L Y P R I V A T E A N D C O N F I D E N T I A L | E19: =Assumptions!D12 -> 43921
Q28: mailto:gina.gibson@jpmorgancazenove.com

Sheet __FDS_SIDEBAR__

Sheet Assumptions
C3: Assumptions
C5: Circular switch
C7: On / off | D7: 1
C9: Key assumptions
C11: Last Historical FYE | D11: 43554
C12: Transaction date | D12: 43921
C14: Enterprise value calculation
C16: Current share price (c) | D16: 165 | E16: p_price
C17: NOSH (m) | D17: 199
C18: Market cap ($m) | D18: =(D16*D17)/100 -> 328.35
C19: Net debt / (cash) ($m) | D19: =-'Company fin forecasts'!B35 -> 84.616814
C20: Minority interests ($m) | D20: 0
C21: Pension liability ($m) | D21: 0
C22: Investment in associates ($m) | D22: 0
C24: EV ($m) | D24: =D18+D19+D20+D21+D22 -> 412.96681

Sheet Company fin forecasts
A1: Happy Hour Co - 5 Year plan
B3: 5 Year Plan
B4: FY20 | C4: FY21 | D4: FY22 | E4: FY23 | F4: FY24
A5: Revenue | B5: 1149.2312 | C5: 1100 | D5: 1353.8374 | E5: 1446.9755 | F5: 1442.6203
A6: YoY growth % | C6: =(C5-B5)/B5 -> -0.042838389 | D6: =D5/C5-1 -> 0.23076126 | E6: =E5/D5-1 -> 0.068795629 | F6: =F5/E5-1 -> -0.0030098203
A7: GP $ | B7: 583.04965 | C7: =C5*C8 -> 550 | D7: 689.15767 | E7: 736.80094 | F7: 753.12426
A8: GM% | B8: =B7/B5 -> 0.50733886 | C8: 0.5 | D8: =D7/D5 -> 0.50904021 | E8: =E7/E5 -> 0.50920071 | F8: =F7/F5 -> 0.52205298
A9: Opex | B9: -522.72818 | C9: -580.01289 | D9: -622.42079 | E9: -662.10014 | F9: -678.11531
A10: Operating profit | B10: =SUM(B9,B7) -> 60.321474 | C10: =C7+C9 -> -30.012889 | D10: =SUM(D9,D7) -> 66.736879 | E10: =SUM(E9,E7) -> 74.700797 | F10: =SUM(F9,F7) -> 75.008951
A11: Operating margin % | B11: =B10/B5 -> 0.052488544 | C11: =C10/C5 -> -0.027284445 | D11: =D10/D5 -> 0.049294605 | E11: =E10/E5 -> 0.051625476 | F11: =F10/F5 -> 0.051994935
A12: Interest and Amortisation | B12: -5.4034795 | C12: -6.34 | D12: -6.2354 | E12: -6.2354 | F12: -6.3407333
A13: Group PBT (Underlying) | B13: =B12+B10 -> 54.917994 | C13: =C10+C12 -> -36.352889 | D13: =D12+D10 -> 60.501479 | E13: =E12+E10 -> 68.465397 | F13: =F12+F10 -> 68.668217
A15: Exceptionals | C15: -18.004469 | D15: -6.752718 | E15: 1.138454 | F15: -4.8650406
A16: Group PBT post exceptionals | B16: =B15+B13 -> 54.917994 | C16: =C13+C15 -> -54.357358 | D16: =D15+D13 -> 53.748761 | E16: =E15+E13 -> 69.603851 | F16: =F15+F13 -> 63.803177
A17: Add back: Interest | B17: 3.1 | C17: 4.1 | D17: 4.1 | E17: 4.1 | F17: 4.1
A18: Add back: Amortisation | B18: 2.1 | C18: 2.0132667 | D18: 1.9086667 | E18: 1.9086667 | F18: 1.9086667
A19: Add back: Depreciation | B19: 34.029215 | C19: 38.442027 | D19: 45.286591 | E19: 49.920877 | F19: 52.891245
A20: EBITDA post exceptionals | B20: =SUM(B16:B19) -> 94.14721 | C20: =C16+C17+C18+C19 -> -9.8020644 | D20: =SUM(D16:D19) -> 105.04402 | E20: =SUM(E16:E19) -> 125.5334 | F20: =SUM(F16:F19) -> 122.70309
A22: Adjust for non-cash exceptionals | B22: 0 | C22: 0 | D22: 0 | E22: 24 | F22: 0
A23: Capex | B23: -36 | C23: -51 | D23: -50 | E23: -50 | F23: -50
A24: Acquisition | B24: -9.2 | C24: -9.2 | D24: 0 | E24: 0 | F24: 0
A25: Tax | B25: -18.064023 | C25: -8.6934141 | D25: -10.931078 | E25: -12.364584 | F25: -12.420051
A26: Interest | B26: -3.1 | C26: -4.1 | D26: -4.1 | E26: -4.1 | F26: -4.1
A27: Working Capital | B27: 6 | C27: 16.111954 | D27: 15.168893 | E27: 11.110217 | F27: 3.9548596
A28: Dividend | B28: -36.6 | C28: -24 | D28: -24 | E28: -24 | F28: -24
A29: Other | B29: 0 | D29: -5 | E29: -5 | F29: -5
A31: Net Cash flow | B31: =SUM(B20:B30) -> -2.8168135 | C31: =C16+C17+C18+C19+C22+C23+C24+C25+C26+C27+C28+C29 -> -90.683524 | D31: =SUM(D20:D30) -> 26.181833 | E31: =SUM(E20:E30) -> 65.179028 | F31: =SUM(F20:F30) -> 31.137897
A32: Free Cash Flow | B32: =B31-B28-B24 -> 42.983186 | C32: =C31-C26 -> -86.583524 | D32: =D31-D28-D24 -> 50.181833 | E32: =E31-E28-E24 -> 89.179028 | F32: =F31-F28-F24 -> 55.137897
A34: Opening Net Debt | B34: -81.8 | C34: =B35 -> -84.616814 | D34: =C35 -> -175.30034 | E34: =D35 -> -149.1185 | F34: =E35 -> -83.939476
A35: Closing Net Debt | B35: =B34+B31 -> -84.616814 | C35: =B35+C31 -> -175.30034 | D35: =D34+D31 -> -149.1185 | E35: =E34+E31 -> -83.939476 | F35: =F34+F31 -> -52.801579
A36: Net debt : EBITDA | B36: =-B35/(B20-B15) -> 0.89877134 | C36: =C35/C20 -> 17.884022 | D36: =-D35/(D20-D15) -> 1.3338359 | E36: =-E35/(E20-E15) -> 0.67478208 | F36: =-F35/(F20-F15) -> 0.41390886
A38: TASK 4 UPDATE: FY21 Revenue revised to $1,100mm, GM% set to 50.0%

Sheet  Financials
C5: Income statement
F7: Actuals | L7: CMD case | Q7: Extrapolations
C9: =TEXT(Assumptions!$D$11,"mmmm")&" YE ($mm)" -> March YE ($mm) | F9: 41729 | G9: =+EDATE(F9,12) -> 42094 | H9: =+EDATE(G9,12) -> 42460 | I9: =+EDATE(H9,12) -> 42825 | J9: =+EDATE(I9,12) -> 43190 | K9: =+EDATE(J9,12) -> 43555 | L9: =+EDATE(K9,12) -> 43921 | M9: =+EDATE(L9,12) -> 44286 | N9: =+EDATE(M9,12) -> 44651 | ... V9: =+EDATE(U9,12) -> 47573
C11: Total revenue | F11: 939.7 | G11: 1004.9 | H11: 1021.5 | I11: 1095 | J11: 1135.1 | K11: 1138.6 | L11: =K11*(1+L13) -> 1149.2312 | M11: =L11*(1+M13) -> 1100 | N11: =M11*(1+N13) -> 1353.8374 | O11: =N11*(1+O13) -> 1446.9755 | P11: =O11*(1+P13) -> 1442.6203 | Q11: =P11*(1+Q13) -> 1471.4728 | R11: =Q11*(1+R13) -> 1497.9593 | S11: =R11*(1+S13) -> 1521.9266 | ... V11: =U11*(1+V13) -> 1577.3699
C12: Management case | L12: =+'Company fin forecasts'!B5 -> 1149.2312 | M12: =+'Company fin forecasts'!C5 -> 1100 | N12: =+'Company fin forecasts'!D5 -> 1353.8374 | O12: =+'Company fin forecasts'!E5 -> 1446.9755 | P12: =+'Company fin forecasts'!F5 -> 1442.6203
C13: % forecast growth | L13: =IF(ISERROR(L12/K11-1),"n.a.",L12/K11-1) -> 0.0093370931 | M13: =IF(ISERROR(M12/L12-1),"n.a.",M12/L12-1) -> -0.042838389 | N13: =IF(ISERROR(N12/M12-1),"n.a.",N12/M12-1) -> 0.23076126 | O13: =IF(ISERROR(O12/N12-1),"n.a.",O12/N12-1) -> 0.068795629 | P13: =IF(ISERROR(P12/O12-1),"n.a.",P12/O12-1) -> -0.0030098203 | Q13: 0.02 | R13: =+AVERAGE(Q13,S13) -> 0.018 | S13: =+AVERAGE(R13,T13) -> 0.016000001 | T13: =+AVERAGE(S13,U13) -> 0.014000001 | U13: =+AVERAGE(T13,V13) -> 0.012 | V13: 0.01
C15: EBITDA | F15: 101.1 | G15: 109.9 | H15: 114.6 | I15: 108.7 | J15: 109.5 | K15: 98.2 | L15: =L11*L18 -> 94.14721 | M15: =M11*M18 -> 8.2024043 | N15: =N11*N18 -> 111.79674 | O15: =O11*O18 -> 124.39494 | P15: =P11*P18 -> 127.56813 | Q15: =Q11*Q18 -> 130.50498 | R15: =R11*R18 -> 133.2465 | S15: =S11*S18 -> 135.77717 | ... V15: =V11*V18 -> 141.96329
C16: =+$C$12 -> Management case | L16: =+('Company fin forecasts'!B20-'Company fin forecasts'!B15) -> 94.14721 | M16: =+('Company fin forecasts'!C20-'Company fin forecasts'!C15) -> 8.2024043 | N16: =+('Company fin forecasts'!D20-'Company fin forecasts'!D15) -> 111.79674 | O16: =+('Company fin forecasts'!E20-'Company fin forecasts'!E15) -> 124.39494 | P16: =+('Company fin forecasts'!F20-'Company fin forecasts'!F15) -> 127.56813
C17: % growth | F17: =IF(ISERROR(F15/E15-1),"n.a.",F15/E15-1) -> n.a. | G17: =IF(ISERROR(G15/F15-1),"n.a.",G15/F15-1) -> 0.087042532 | H17: =IF(ISERROR(H15/G15-1),"n.a.",H15/G15-1) -> 0.042766151 | I17: =IF(ISERROR(I15/H15-1),"n.a.",I15/H15-1) -> -0.051483421 | J17: =IF(ISERROR(J15/I15-1),"n.a.",J15/I15-1) -> 0.0073597056 | K17: =IF(ISERROR(K15/J15-1),"n.a.",K15/J15-1) -> -0.10319635 | L17: =IF(ISERROR(L15/K15-1),"n.a.",L15/K15-1) -> -0.041270777 | M17: =IF(ISERROR(M15/L15-1),"n.a.",M15/L15-1) -> -0.91287682 | ... V17: =IF(ISERROR(V15/U15-1),"n.a.",V15/U15-1) -> 0.012948785
C18: % forecast margin | L18: =IF(ISERROR(L16/L$12),"n.a.",L16/L$12) -> 0.081921904 | M18: =IF(ISERROR(M16/M$12),"n.a.",M16/M$12) -> 0.0074567312 | N18: =IF(ISERROR(N16/N$12),"n.a.",N16/N$12) -> 0.08257767 | O18: =IF(ISERROR(O16/O$12),"n.a.",O16/O$12) -> 0.085968935 | P18: =IF(ISERROR(P16/P$12),"n.a.",P16/P$12) -> 0.088428068 | Q18: =+AVERAGE(P18,R18) -> 0.088690044 | R18: =+AVERAGE(Q18,S18) -> 0.088952026 | S18: =+AVERAGE(R18,T18) -> 0.089214015 | T18: =+AVERAGE(S18,U18) -> 0.089476009 | U18: =+AVERAGE(T18,V18) -> 0.089738004 | V18: 0.09
C20: Depreciation and amortisation | F20: =-F15+F25 -> -23.3 | G20: =-G15+G25 -> -25.3 | H20: =-H15+H25 -> -30.1 | I20: =-I15+I25 -> -31.6 | J20: =-J15+J25 -> -34.9 | K20: =-K15+K25 -> -36 | L20: =+(('Company fin forecasts'!B18+'Company fin forecasts'!B19))*-1 -> -36.129215 | M20: =+(('Company fin forecasts'!C18+'Company fin forecasts'!C19))*-1 -> -40.455294 | N20: =+(('Company fin forecasts'!D18+'Company fin forecasts'!D19))*-1 -> -47.195258 | O20: =+(('Company fin forecasts'!E18+'Company fin forecasts'!E19))*-1 -> -51.829544 | P20: =+(('Company fin forecasts'!F18+'Company fin forecasts'!F19))*-1 -> -54.799912 | Q20: =Q22*Q40 -> -53.583337 | R20: =R22*R40 -> -52.366724 | S20: =S22*S40 -> -51.150072 | T20: =T22*T40 -> -49.933391 | U20: =U22*U40 -> -48.716696 | V20: =V22*V40 -> -47.5
C21: % growth | F21: =IF(ISERROR(F20/E20-1),"n.a.",F20/E20-1) -> n.a. | G21: =IF(ISERROR(G20/F20-1),"n.a.",G20/F20-1) -> 0.08583691 | H21: =IF(ISERROR(H20/G20-1),"n.a.",H20/G20-1) -> 0.18972332 | I21: =IF(ISERROR(I20/H20-1),"n.a.",I20/H20-1) -> 0.049833887 | J21: =IF(ISERROR(J20/I20-1),"n.a.",J20/I20-1) -> 0.10443038 | K21: =IF(ISERROR(K20/J20-1),"n.a.",K20/J20-1) -> 0.031518625 | L21: =IF(ISERROR(L20/K20-1),"n.a.",L20/K20-1) -> 0.0035893167 | M21: =IF(ISERROR(M20/L20-1),"n.a.",M20/L20-1) -> 0.11973906 | ... V21: =IF(ISERROR(V20/U20-1),"n.a.",V20/U20-1) -> -0.024974919
C22: % capex | F22: =IF(ISERROR(F20/F$40),"n.a.",F20/F$40) -> 0.76644737 | G22: =IF(ISERROR(G20/G$40),"n.a.",G20/G$40) -> 0.67466667 | H22: =IF(ISERROR(H20/H$40),"n.a.",H20/H$40) -> 0.74689826 | I22: =IF(ISERROR(I20/I$40),"n.a.",I20/I$40) -> 0.87534626 | J22: =IF(ISERROR(J20/J$40),"n.a.",J20/J$40) -> 0.93565684 | K22: =IF(ISERROR(K20/K$40),"n.a.",K20/K$40) -> 1.1612903 | L22: =IF(ISERROR(L20/L$40),"n.a.",L20/L$40) -> 1.0035893 | M22: =IF(ISERROR(M20/M$40),"n.a.",M20/M$40) -> 0.79324105 | ... P22: =IF(ISERROR(P20/P$40),"n.a.",P20/P$40) -> 1.0959982 | Q22: =+AVERAGE(P22,R22) -> 1.0716664 | R22: =+AVERAGE(Q22,S22) -> 1.0473339 | S22: =+AVERAGE(R22,T22) -> 1.0230009 | T22: =+AVERAGE(S22,U22) -> 0.99866739 | U22: =+AVERAGE(T22,V22) -> 0.97433369 | V22: 0.95
C23: % margin | F23: =F20/F11*-1 -> 0.024795147 | G23: =G20/G11*-1 -> 0.025176634 | H23: =H20/H11*-1 -> 0.029466471 | I23: =I20/I11*-1 -> 0.028858447 | J23: =J20/J11*-1 -> 0.03074619 | K23: =K20/K11*-1 -> 0.031617776 | L23: =L20/L11*-1 -> 0.031437725 | M23: =M20/M11*-1 -> 0.03677754 | ... V23: =V20/V11*-1 -> 0.030113418
C25: EBIT | F25: 77.8 | G25: 84.6 | H25: 84.5 | I25: 77.1 | J25: 74.6 | K25: 62.2 | L25: =+L15+L20 -> 58.017994 | M25: =+M15+M20 -> -32.252889 | N25: =+N15+N20 -> 64.601479 | O25: =+O15+O20 -> 72.565397 | P25: =+P15+P20 -> 72.768217 | Q25: =Q15+Q20 -> 76.921639 | R25: =R15+R20 -> 80.879778 | S25: =S15+S20 -> 84.627102 | T25: =T15+T20 -> 88.148983 | U25: =U15+U20 -> 91.431843 | V25: =V15+V20 -> 94.463292
C26: % growth | F26: =IF(ISERROR(F25/E25-1),"n.a.",F25/E25-1) -> n.a. | G26: =IF(ISERROR(G25/F25-1),"n.a.",G25/F25-1) -> 0.087403599 | H26: =IF(ISERROR(H25/G25-1),"n.a.",H25/G25-1) -> -0.0011820331 | I26: =IF(ISERROR(I25/H25-1),"n.a.",I25/H25-1) -> -0.087573964 | J26: =IF(ISERROR(J25/I25-1),"n.a.",J25/I25-1) -> -0.032425422 | K26: =IF(ISERROR(K25/J25-1),"n.a.",K25/J25-1) -> -0.16621984 | L26: =IF(ISERROR(L25/K25-1),"n.a.",L25/K25-1) -> -0.067234819 | M26: =IF(ISERROR(M25/L25-1),"n.a.",M25/L25-1) -> -1.5559118 | ... V26: =IF(ISERROR(V25/U25-1),"n.a.",V25/U25-1) -> 0.033155285
C27: % margin | F27: =IF(ISERROR(F25/F$11),"n.a.",F25/F$11) -> 0.082792381 | G27: =IF(ISERROR(G25/G$11),"n.a.",G25/G$11) -> 0.084187481 | H27: =IF(ISERROR(H25/H$11),"n.a.",H25/H$11) -> 0.082721488 | I27: =IF(ISERROR(I25/I$11),"n.a.",I25/I$11) -> 0.070410959 | J27: =IF(ISERROR(J25/J$11),"n.a.",J25/J$11) -> 0.065721082 | K27: =IF(ISERROR(K25/K$11),"n.a.",K25/K$11) -> 0.054628491 | L27: =IF(ISERROR(L25/L$11),"n.a.",L25/L$11) -> 0.050484179 | M27: =IF(ISERROR(M25/M$11),"n.a.",M25/M$11) -> -0.029320808 | ... V27: =IF(ISERROR(V25/V$11),"n.a.",V25/V$11) -> 0.059886582
C29: % tax rate | K29: 0.19 | L29: 0.19 | M29: 0.17 | N29: =M29 -> 0.17 | O29: =N29 -> 0.17 | P29: =O29 -> 0.17 | Q29: =P29 -> 0.17 | R29: =Q29 -> 0.17 | S29: =R29 -> 0.17 | T29: =S29 -> 0.17 | U29: =T29 -> 0.17 | V29: =U29 -> 0.17
B31: x | C31: Net income | F31: 55.5 | G31: 65.8 | H31: 64.9 | I31: 59.5 | J31: 58.4 | K31: 48.3 | L31: =+('Company fin forecasts'!B13+'Company fin forecasts'!I13)*(1-L29) -> 44.483575 | M31: =+('Company fin forecasts'!C13+'Company fin forecasts'!J13)*(1-M29) -> -30.172898 | N31: =+('Company fin forecasts'!D13+'Company fin forecasts'!K13)*(1-N29) -> 50.216227 | O31: =+('Company fin forecasts'!E13+'Company fin forecasts'!L13)*(1-O29) -> 56.82628 | P31: =+('Company fin forecasts'!F13+'Company fin forecasts'!M13)*(1-P29) -> 56.99462
C32: % growth | F32: =IF(ISERROR(F31/E31-1),"n.a.",F31/E31-1) -> n.a. | G32: =IF(ISERROR(G31/F31-1),"n.a.",G31/F31-1) -> 0.18558559 | H32: =IF(ISERROR(H31/G31-1),"n.a.",H31/G31-1) -> -0.013677812 | I32: =IF(ISERROR(I31/H31-1),"n.a.",I31/H31-1) -> -0.083204931 | J32: =IF(ISERROR(J31/I31-1),"n.a.",J31/I31-1) -> -0.018487395 | K32: =IF(ISERROR(K31/J31-1),"n.a.",K31/J31-1) -> -0.17294521 | L32: =IF(ISERROR(L31/K31-1),"n.a.",L31/K31-1) -> -0.079015003 | M32: =IF(ISERROR(M31/L31-1),"n.a.",M31/L31-1) -> -1.678293 | ... P32: =IF(ISERROR(P31/O31-1),"n.a.",P31/O31-1) -> 0.0029623691
C33: % margin | F33: =IF(ISERROR(F31/F$11),"n.a.",F31/F$11) -> 0.059061403 | G33: =IF(ISERROR(G31/G$11),"n.a.",G31/G$11) -> 0.065479152 | H33: =IF(ISERROR(H31/H$11),"n.a.",H31/H$11) -> 0.063534019 | I33: =IF(ISERROR(I31/I$11),"n.a.",I31/I$11) -> 0.0543379 | J33: =IF(ISERROR(J31/J$11),"n.a.",J31/J$11) -> 0.051449212 | K33: =IF(ISERROR(K31/K$11),"n.a.",K31/K$11) -> 0.042420516 | L33: =IF(ISERROR(L31/L$11),"n.a.",L31/L$11) -> 0.038707246 | M33: =IF(ISERROR(M31/M$11),"n.a.",M31/M$11) -> -0.027429907 | ... P33: =IF(ISERROR(P31/P$11),"n.a.",P31/P$11) -> 0.039507706
C38: Cashflow statement
C40: Capex | F40: -30.4 | G40: -37.5 | H40: -40.3 | I40: -36.1 | J40: -37.3 | K40: -31 | L40: =+('Company fin forecasts'!B23) -> -36 | M40: =+('Company fin forecasts'!C23) -> -51 | N40: =+('Company fin forecasts'!D23) -> -50 | O40: =+('Company fin forecasts'!E23) -> -50 | P40: =+('Company fin forecasts'!F23) -> -50 | Q40: =+P40 -> -50 | R40: =+Q40 -> -50 | S40: =+R40 -> -50 | T40: =+S40 -> -50 | U40: =+T40 -> -50 | V40: =+U40 -> -50
C41: % growth | F41: =IF(ISERROR(F40/E40-1),"n.a.",F40/E40-1) -> n.a. | G41: =IF(ISERROR(G40/F40-1),"n.a.",G40/F40-1) -> 0.23355263 | H41: =IF(ISERROR(H40/G40-1),"n.a.",H40/G40-1) -> 0.074666667 | I41: =IF(ISERROR(I40/H40-1),"n.a.",I40/H40-1) -> -0.10421836 | J41: =IF(ISERROR(J40/I40-1),"n.a.",J40/I40-1) -> 0.033240997 | K41: =IF(ISERROR(K40/J40-1),"n.a.",K40/J40-1) -> -0.1689008 | L41: =IF(ISERROR(L40/K40-1),"n.a.",L40/K40-1) -> 0.16129032 | M41: =IF(ISERROR(M40/L40-1),"n.a.",M40/L40-1) -> 0.41666667 | ... V41: =IF(ISERROR(V40/U40-1),"n.a.",V40/U40-1) -> 0
C42: % sales | F42: =IF(ISERROR(-F40/F$11),"n.a.",-F40/F$11) -> 0.03235075 | G42: =IF(ISERROR(-G40/G$11),"n.a.",-G40/G$11) -> 0.037317146 | H42: =IF(ISERROR(-H40/H$11),"n.a.",-H40/H$11) -> 0.039451787 | I42: =IF(ISERROR(-I40/I$11),"n.a.",-I40/I$11) -> 0.032968037 | J42: =IF(ISERROR(-J40/J$11),"n.a.",-J40/J$11) -> 0.032860541 | K42: =IF(ISERROR(-K40/K$11),"n.a.",-K40/K$11) -> 0.027226418 | L42: =IF(ISERROR(-L40/L$11),"n.a.",-L40/L$11) -> 0.031325289 | M42: =IF(ISERROR(-M40/M$11),"n.a.",-M40/M$11) -> 0.046363636 | ... V42: =IF(ISERROR(-V40/V$11),"n.a.",-V40/V$11) -> 0.031698335
C43: % Cash conversion | F43: =(F15+F40)/F15 -> 0.69930762 | G43: =(G15+G40)/G15 -> 0.65878071 | H43: =(H15+H40)/H15 -> 0.64834206 | I43: =(I15+I40)/I15 -> 0.66789328 | J43: =(J15+J40)/J15 -> 0.65936073 | K43: =(K15+K40)/K15 -> 0.68431772 | L43: =(L15+L40)/L15 -> 0.61762011 | M43: =(M15+M40)/M15 -> -5.2176891 | ... V43: =(V15+V40)/V15 -> 0.64779628
C45: Change in Working Capital | F45: =-17+1+10.7 -> -5.3 | G45: =0.9-3+27.2 -> 25.1 | H45: =-8.6-4.9+2.3 -> -11.2 | I45: =-33.2+2.3+14.6 -> -16.3 | J45: =-4.4+2.4-10.6 -> -12.6 | K45: =11.9-3.1-19.2 -> -10.4 | L45: =+('Company fin forecasts'!B27) -> 6 | M45: =+('Company fin forecasts'!C27) -> 16.111954 | N45: =+('Company fin forecasts'!D27) -> 15.168893 | O45: =+('Company fin forecasts'!E27) -> 11.110217 | P45: =+('Company fin forecasts'!F27) -> 3.9548596 | Q45: =Q47*Q11 -> 0 | R45: =R47*R11 -> 0 | S45: =S47*S11 -> 0 | T45: =T47*T11 -> 0 | U45: =U47*U11 -> 0 | V45: =V47*V11 -> 0
C46: % growth | F46: =IF(ISERROR(F45/E45-1),"n.a.",F45/E45-1) -> n.a. | G46: =IF(ISERROR(G45/F45-1),"n.a.",G45/F45-1) -> -5.7358491 | H46: =IF(ISERROR(H45/G45-1),"n.a.",H45/G45-1) -> -1.4462151 | I46: =IF(ISERROR(I45/H45-1),"n.a.",I45/H45-1) -> 0.45535714 | J46: =IF(ISERROR(J45/I45-1),"n.a.",J45/I45-1) -> -0.22699387 | K46: =IF(ISERROR(K45/J45-1),"n.a.",K45/J45-1) -> -0.17460317 | L46: =IF(ISERROR(L45/K45-1),"n.a.",L45/K45-1) -> -1.5769231 | M46: =IF(ISERROR(M45/L45-1),"n.a.",M45/L45-1) -> 1.6853257 | ... V46: =IF(ISERROR(V45/U45-1),"n.a.",V45/U45-1) -> n.a.
C47: % sales | F47: =IF(ISERROR(F45/F$11),"n.a.",F45/F$11) -> -0.0056400979 | G47: =IF(ISERROR(G45/G$11),"n.a.",G45/G$11) -> 0.02497761 | H47: =IF(ISERROR(H45/H$11),"n.a.",H45/H$11) -> -0.010964268 | I47: =IF(ISERROR(I45/I$11),"n.a.",I45/I$11) -> -0.014885845 | J47: =IF(ISERROR(J45/J$11),"n.a.",J45/J$11) -> -0.011100344 | K47: =IF(ISERROR(K45/K$11),"n.a.",K45/K$11) -> -0.0091340242 | L47: =IF(ISERROR(L45/L$11),"n.a.",L45/L$11) -> 0.0052208815 | M47: =IF(ISERROR(M45/M$11),"n.a.",M45/M$11) -> 0.014647231 | ... P47: =IF(ISERROR(P45/P$11),"n.a.",P45/P$11) -> 0.0027414417 | Q47: 0 | R47: =Q47 -> 0 | S47: =R47 -> 0 | T47: =S47 -> 0 | U47: =T47 -> 0 | V47: =U47 -> 0
C49: Other Cashflows | J49: -1.5 | K49: 0.74 | L49: =+('Company fin forecasts'!B29) -> 0 | M49: =+('Company fin forecasts'!C29) -> 0 | N49: =+('Company fin forecasts'!D29) -> -5 | O49: =+('Company fin forecasts'!E29) -> -5 | P49: =+('Company fin forecasts'!F29) -> -5 | Q49: -5 | R49: =+Q49 -> -5 | S49: =+R49 -> -5 | T49: =+S49 -> -5 | U49: =+T49 -> -5 | V49: =+U49 -> -5
C50: % growth | F50: =IF(ISERROR(F49/E49-1),"n.a.",F49/E49-1) -> n.a. | G50: =IF(ISERROR(G49/F49-1),"n.a.",G49/F49-1) -> n.a. | H50: =IF(ISERROR(H49/G49-1),"n.a.",H49/G49-1) -> n.a. | I50: =IF(ISERROR(I49/H49-1),"n.a.",I49/H49-1) -> n.a. | J50: =IF(ISERROR(J49/I49-1),"n.a.",J49/I49-1) -> n.a. | K50: =IF(ISERROR(K49/J49-1),"n.a.",K49/J49-1) -> -1.4933333 | L50: =IF(ISERROR(L49/K49-1),"n.a.",L49/K49-1) -> -1 | M50: =IF(ISERROR(M49/L49-1),"n.a.",M49/L49-1) -> n.a. | ... V50: =IF(ISERROR(V49/U49-1),"n.a.",V49/U49-1) -> 0
C51: % sales | F51: =IF(ISERROR(-F49/F$11),"n.a.",-F49/F$11) -> 0 | G51: =IF(ISERROR(-G49/G$11),"n.a.",-G49/G$11) -> 0 | H51: =IF(ISERROR(-H49/H$11),"n.a.",-H49/H$11) -> 0 | I51: =IF(ISERROR(-I49/I$11),"n.a.",-I49/I$11) -> 0 | J51: =IF(ISERROR(-J49/J$11),"n.a.",-J49/J$11) -> 0.0013214695 | K51: =IF(ISERROR(-K49/K$11),"n.a.",-K49/K$11) -> -0.00064992096 | L51: =IF(ISERROR(-L49/L$11),"n.a.",-L49/L$11) -> 0 | M51: =IF(ISERROR(-M49/M$11),"n.a.",-M49/M$11) -> 0 | ... V51: =IF(ISERROR(-V49/V$11),"n.a.",-V49/V$11) -> 0.0031698335
C53: Exceptional items | J53: 0 | K53: 0 | L53: =+('Company fin forecasts'!B15+'Company fin forecasts'!B22) -> 0 | M53: =+('Company fin forecasts'!C15+'Company fin forecasts'!C22) -> -18.004469 | N53: =+('Company fin forecasts'!D15+'Company fin forecasts'!D22) -> -6.752718 | O53: =+('Company fin forecasts'!E15+'Company fin forecasts'!E22) -> 25.138454 | P53: =+('Company fin forecasts'!F15+'Company fin forecasts'!F22) -> -4.8650406 | Q53: 0 | R53: =+Q53 -> 0 | S53: =+R53 -> 0 | T53: =+S53 -> 0 | U53: =+T53 -> 0 | V53: =+U53 -> 0
C54: % growth | F54: =IF(ISERROR(F53/E53-1),"n.a.",F53/E53-1) -> n.a. | G54: =IF(ISERROR(G53/F53-1),"n.a.",G53/F53-1) -> n.a. | H54: =IF(ISERROR(H53/G53-1),"n.a.",H53/G53-1) -> n.a. | I54: =IF(ISERROR(I53/H53-1),"n.a.",I53/H53-1) -> n.a. | J54: =IF(ISERROR(J53/I53-1),"n.a.",J53/I53-1) -> n.a. | K54: =IF(ISERROR(K53/J53-1),"n.a.",K53/J53-1) -> n.a. | L54: =IF(ISERROR(L53/K53-1),"n.a.",L53/K53-1) -> n.a. | M54: =IF(ISERROR(M53/L53-1),"n.a.",M53/L53-1) -> n.a. | ... V54: =IF(ISERROR(V53/U53-1),"n.a.",V53/U53-1) -> n.a.
C55: % sales | F55: =IF(ISERROR(-F53/F$11),"n.a.",-F53/F$11) -> 0 | G55: =IF(ISERROR(-G53/G$11),"n.a.",-G53/G$11) -> 0 | H55: =IF(ISERROR(-H53/H$11),"n.a.",-H53/H$11) -> 0 | I55: =IF(ISERROR(-I53/I$11),"n.a.",-I53/I$11) -> 0 | J55: =IF(ISERROR(-J53/J$11),"n.a.",-J53/J$11) -> 0 | K55: =IF(ISERROR(-K53/K$11),"n.a.",-K53/K$11) -> 0 | L55: =IF(ISERROR(-L53/L$11),"n.a.",-L53/L$11) -> 0 | M55: =IF(ISERROR(-M53/M$11),"n.a.",-M53/M$11) -> 0.016367699 | ... V55: =IF(ISERROR(-V53/V$11),"n.a.",-V53/V$11) -> 0
C57: Summary financials
C58: March Y/E | F58: =F9 -> 41729 | G58: =G9 -> 42094 | H58: =H9 -> 42460 | I58: =I9 -> 42825 | J58: =J9 -> 43190 | K58: =K9 -> 43555 | L58: =L9 -> 43921 | M58: =M9 -> 44286 | ... V58: =V9 -> 47573
C60: Revenue | F60: =F11 -> 939.7 | G60: =G11 -> 1004.9 | H60: =H11 -> 1021.5 | I60: =I11 -> 1095 | J60: =J11 -> 1135.1 | K60: =K11 -> 1138.6 | L60: =L11 -> 1149.2312 | M60: =M11 -> 1100 | ... V60: =V11 -> 1577.3699
C61: % growth | F61: =IF(ISERROR(F60/E60-1),"n.a.",F60/E60-1) -> n.a. | G61: =IF(ISERROR(G60/F60-1),"n.a.",G60/F60-1) -> 0.069383846 | H61: =IF(ISERROR(H60/G60-1),"n.a.",H60/G60-1) -> 0.016519057 | I61: =IF(ISERROR(I60/H60-1),"n.a.",I60/H60-1) -> 0.07195301 | J61: =IF(ISERROR(J60/I60-1),"n.a.",J60/I60-1) -> 0.036621005 | K61: =IF(ISERROR(K60/J60-1),"n.a.",K60/J60-1) -> 0.0030834288 | L61: =IF(ISERROR(L60/K60-1),"n.a.",L60/K60-1) -> 0.0093370931 | M61: =IF(ISERROR(M60/L60-1),"n.a.",M60/L60-1) -> -0.042838389 | ... V61: =IF(ISERROR(V60/U60-1),"n.a.",V60/U60-1) -> 0.01
C62: EBITDA | F62: =F15 -> 101.1 | G62: =G15 -> 109.9 | H62: =H15 -> 114.6 | I62: =I15 -> 108.7 | J62: =J15 -> 109.5 | K62: =K15 -> 98.2 | L62: =L15 -> 94.14721 | M62: =M15 -> 8.2024043 | ... V62: =V15 -> 141.96329
...

Sheet DCF input
D3: DCF
D5: Key assumptions
D7: Transaction date | F7: =Assumptions!D12 -> 43921
D8: Next financial YE | F8: =EDATE(F7,12) -> 44286
D9: Perpetuity growth rate | F9: 0.005
D10: TV exit EBITDA multiple | F10: 8.5
D11: WACC used for sensitivity analysis | F11: 0.085
D14: DCF FCF Calculation
C17: Stub period | G17: =G22-$F$7 -> -42821 | H17: =H22-$F$7 -> -366 | I17: =I22-$F$7 -> 0 | J17: =J22-$F$7 -> 365 | K17: =K22-$F$7 -> 730 | L17: =L22-$F$7 -> 1095 | M17: =M22-$F$7 -> 1461 | N17: =N22-$F$7 -> 1826 | ... S17: =S22-$F$7 -> 3652
C18: Stub factor | G18: =IF(G17<0,100%,IF(G17>365.25,0,1-((G22-$F$7)/365.25))) -> 1 | H18: =IF(H17<0,100%,IF(H17>365.25,0,1-((H22-$F$7)/365.25))) -> 1 | I18: =IF(I17<0,100%,IF(I17>365.25,0,1-((I22-$F$7)/365.25))) -> 1 | J18: =IF(J17<0,100%,IF(J17>365.25,0,1-((J22-$F$7)/365.25))) -> 0.0006844627 | K18: =IF(K17<0,100%,IF(K17>365.25,0,1-((K22-$F$7)/365.25))) -> 0 | L18: =IF(L17<0,100%,IF(L17>365.25,0,1-((L22-$F$7)/365.25))) -> 0 | M18: =IF(M17<0,100%,IF(M17>365.25,0,1-((M22-$F$7)/365.25))) -> 0 | N18: =IF(N17<0,100%,IF(N17>365.25,0,1-((N22-$F$7)/365.25))) -> 0 | ... S18: =IF(S17<0,100%,IF(S17>365.25,0,1-((S22-$F$7)/365.25))) -> 0
F20: Actuals | I20: Estimates
D22: =TEXT(Assumptions!$D$11,"mmmm")&" YE ($mm)" -> March YE ($mm) | F22: =' Financials'!I58 -> 42825 | G22: ='Company fin forecasts'!C5 -> 1100 | H22: =' Financials'!K58 -> 43555 | I22: =' Financials'!L58 -> 43921 | J22: =' Financials'!M58 -> 44286 | K22: =' Financials'!N58 -> 44651 | L22: =' Financials'!O58 -> 45016 | M22: =' Financials'!P58 -> 45382 | N22: =' Financials'!Q58 -> 45747 | O22: =' Financials'!R58 -> 46112 | ... S22: =' Financials'!V58 -> 47573
D24: Revenue | F24: =' Financials'!I60 -> 1095 | G24: =' Financials'!J60 -> 1135.1 | H24: =' Financials'!K60 -> 1138.6 | I24: =' Financials'!L60 -> 1149.2312 | J24: =' Financials'!M60 -> 1100 | K24: =' Financials'!N60 -> 1353.8374 | L24: =' Financials'!O60 -> 1446.9755 | M24: =' Financials'!P60 -> 1442.6203 | ... S24: =' Financials'!V60 -> 1577.3699
D25: % growth | G25: ='Company fin forecasts'!C20 -> -9.8020644 | H25: =IF(ISERROR(H24/G24-1),"n.a.",(H24/G24-1)) -> 0.0030834288 | I25: =IF(ISERROR(I24/G24-1),"n.a.",(I24/G24-1)) -> 0.012449312 | J25: =IF(ISERROR(J24/I24-1),"n.a.",(J24/I24-1)) -> -0.042838389 | K25: =IF(ISERROR(K24/J24-1),"n.a.",(K24/J24-1)) -> 0.23076126 | L25: =IF(ISERROR(L24/K24-1),"n.a.",(L24/K24-1)) -> 0.068795629 | M25: =IF(ISERROR(M24/L24-1),"n.a.",(M24/L24-1)) -> -0.0030098203 | N25: =IF(ISERROR(N24/M24-1),"n.a.",(N24/M24-1)) -> 0.02 | O25: =IF(ISERROR(O24/N24-1),"n.a.",(O24/N24-1)) -> 0.018000001 | P25: =IF(ISERROR(P24/O24-1),"n.a.",(P24/O24-1)) -> 0.016000001 | Q25: =IF(ISERROR(Q24/P24-1),"n.a.",(Q24/P24-1)) -> 0.014000001 | ... S25: =IF(ISERROR(S24/R24-1),"n.a.",(S24/R24-1)) -> 0.01
D27: EBITDA | F27: =+' Financials'!I62 -> 108.7 | G27: =+' Financials'!J62 -> 109.5 | H27: =+' Financials'!K62 -> 98.2 | I27: =+' Financials'!L62 -> 94.14721 | J27: =+' Financials'!M62 -> 8.2024043 | K27: =+' Financials'!N62 -> 111.79674 | L27: =+' Financials'!O62 -> 124.39494 | M27: =+' Financials'!P62 -> 127.56813 | ... S27: =+' Financials'!V62 -> 141.96329
D28: % margin | F28: =IF(ISERROR(F27/F$24),"n.a.",(F27/F$24)) -> 0.099269406 | G28: =IF(ISERROR(G27/G$24),"n.a.",(G27/G$24)) -> 0.096467272 | H28: =IF(ISERROR(H27/H$24),"n.a.",(H27/H$24)) -> 0.086246267 | I28: =IF(ISERROR(I27/I$24),"n.a.",(I27/I$24)) -> 0.081921904 | J28: =IF(ISERROR(J27/J$24),"n.a.",(J27/J$24)) -> 0.0074567312 | K28: =IF(ISERROR(K27/K$24),"n.a.",(K27/K$24)) -> 0.08257767 | L28: =IF(ISERROR(L27/L$24),"n.a.",(L27/L$24)) -> 0.085968935 | M28: =IF(ISERROR(M27/M$24),"n.a.",(M27/M$24)) -> 0.088428068 | ... S28: =IF(ISERROR(S27/S$24),"n.a.",(S27/S$24)) -> 0.09
D29: % growth | G29: ='Company fin forecasts'!C19 -> 38.442027 | H29: =IF(ISERROR(H27/G27-1),"n.a.",(H27/G27-1)) -> -0.10319635 | I29: =IF(ISERROR(I27/H27-1),"n.a.",(I27/H27-1)) -> -0.041270777 | J29: =IF(ISERROR(J27/I27-1),"n.a.",(J27/I27-1)) -> -0.91287682 | K29: =IF(ISERROR(K27/J27-1),"n.a.",(K27/J27-1)) -> 12.629752 | L29: =IF(ISERROR(L27/K27-1),"n.a.",(L27/K27-1)) -> 0.11268848 | M29: =IF(ISERROR(M27/L27-1),"n.a.",(M27/L27-1)) -> 0.025508982 | N29: =IF(ISERROR(N27/M27-1),"n.a.",(N27/M27-1)) -> 0.023021795 | O29: =IF(ISERROR(O27/N27-1),"n.a.",(O27/N27-1)) -> 0.021007058 | ... S29: =IF(ISERROR(S27/R27-1),"n.a.",(S27/R27-1)) -> 0.012948785
D31: D&A | F31: =' Financials'!I65 -> -31.6 | G31: =' Financials'!J65 -> -34.9 | H31: =' Financials'!K65 -> -36 | I31: =' Financials'!L65 -> -36.129215 | J31: =' Financials'!M65 -> -40.455294 | K31: =' Financials'!N65 -> -47.195258 | L31: =' Financials'!O65 -> -51.829544 | M31: =' Financials'!P65 -> -54.799912 | ... S31: =' Financials'!V65 -> -47.5
D32: % sales | F32: =IF(ISERROR(-F31/F$24),"n.a.",(-F31/F$24)) -> 0.028858447 | G32: =IF(ISERROR(-G31/G$24),"n.a.",(-G31/G$24)) -> 0.03074619 | H32: =IF(ISERROR(-H31/H$24),"n.a.",(-H31/H$24)) -> 0.031617776 | I32: =IF(ISERROR(-I31/I$24),"n.a.",(-I31/I$24)) -> 0.031437725 | J32: =IF(ISERROR(-J31/J$24),"n.a.",(-J31/J$24)) -> 0.03677754 | K32: =IF(ISERROR(-K31/K$24),"n.a.",(-K31/K$24)) -> 0.034860359 | L32: =IF(ISERROR(-L31/L$24),"n.a.",(-L31/L$24)) -> 0.035819227 | M32: =IF(ISERROR(-M31/M$24),"n.a.",(-M31/M$24)) -> 0.037986371 | ... S32: =IF(ISERROR(-S31/S$24),"n.a.",(-S31/S$24)) -> 0.030113418
D33: % of capex | F33: =F31/F48 -> 0.87534626 | G33: ='Company fin forecasts'!C10 -> -30.012889 | H33: =H31/H48 -> 1.1612903 | I33: =I31/I48 -> 1.0035893 | J33: =J31/J48 -> 0.79324105 | K33: =K31/K48 -> 0.94390515 | L33: =L31/L48 -> 1.0365909 | M33: =M31/M48 -> 1.0959982 | N33: =N31/N48 -> 1.0716674 | O33: =O31/O48 -> 1.0473355 | ... S33: =S31/S48 -> 0.95
D35: EBIT | F35: =F27+F31 -> 77.1 | G35: =G27+G31 -> 74.6 | H35: =H27+H31 -> 62.2 | I35: =I27+I31 -> 58.017994 | J35: =J27+J31 -> -32.252889 | K35: =K27+K31 -> 64.601479 | L35: =L27+L31 -> 72.565397 | M35: =M27+M31 -> 72.768217 | ... S35: =S27+S31 -> 94.463292
D36: % margin | F36: =IF(ISERROR(F35/F$24),"n.a.",(F35/F$24)) -> 0.070410959 | G36: =IF(ISERROR(G35/G$24),"n.a.",(G35/G$24)) -> 0.065721082 | H36: =IF(ISERROR(H35/H$24),"n.a.",(H35/H$24)) -> 0.054628491 | I36: =IF(ISERROR(I35/I$24),"n.a.",(I35/I$24)) -> 0.050484179 | J36: =IF(ISERROR(J35/J$24),"n.a.",(J35/J$24)) -> -0.029320808 | K36: =IF(ISERROR(K35/K$24),"n.a.",(K35/K$24)) -> 0.04771731 | L36: =IF(ISERROR(L35/L$24),"n.a.",(L35/L$24)) -> 0.050149708 | M36: =IF(ISERROR(M35/M$24),"n.a.",(M35/M$24)) -> 0.050441696 | ... S36: =IF(ISERROR(S35/S$24),"n.a.",(S35/S$24)) -> 0.059886582
D37: % growth | G37: ='Company fin forecasts'!C25 -> -8.6934141 | H37: =IF(ISERROR(H35/G35-1),"n.a.",(H35/G35-1)) -> -0.16621984 | I37: =IF(ISERROR(I35/H35-1),"n.a.",(I35/H35-1)) -> -0.067234819 | J37: =IF(ISERROR(J35/I35-1),"n.a.",(J35/I35-1)) -> -1.5559118 | K37: =IF(ISERROR(K35/J35-1),"n.a.",(K35/J35-1)) -> -3.0029672 | L37: =IF(ISERROR(L35/K35-1),"n.a.",(L35/K35-1)) -> 0.12327766 | M37: =IF(ISERROR(M35/L35-1),"n.a.",(M35/L35-1)) -> 0.002794993 | N37: =IF(ISERROR(N35/M35-1),"n.a.",(N35/M35-1)) -> 0.057076953 | O37: =IF(ISERROR(O35/N35-1),"n.a.",(O35/N35-1)) -> 0.051456568 | ... S37: =IF(ISERROR(S35/R35-1),"n.a.",(S35/R35-1)) -> 0.033155504
D39: Tax | I39: =-I35*I40 -> -11.023419 | J39: =-J35*J40 -> 5.4829912 | K39: =-K35*K40 -> -10.982251 | L39: =-L35*L40 -> -12.336118 | M39: =-M35*M40 -> -12.370597 | N39: =-N35*N40 -> -13.076673 | O39: =-O35*O40 -> -13.749554 | P39: =-P35*P40 -> -14.386599 | ... S39: =-S35*S40 -> -16.05876
D40: % tax rate | I40: =+' Financials'!L29 -> 0.19 | J40: =+' Financials'!M29 -> 0.17 | K40: =+' Financials'!N29 -> 0.17 | L40: =+' Financials'!O29 -> 0.17 | M40: =+' Financials'!P29 -> 0.17 | N40: =+' Financials'!Q29 -> 0.17 | O40: =+' Financials'!R29 -> 0.17 | P40: =+' Financials'!S29 -> 0.17 | ... S40: =+' Financials'!V29 -> 0.17
D42: EBIAT | I42: =I35+I39 -> 46.994575 | J42: =J35+J39 -> -26.769898 | K42: =K35+K39 -> 53.619227 | L42: =L35+L39 -> 60.22928 | M42: =M35+M39 -> 60.39762 | N42: =N35+N39 -> 63.844932 | O42: =O35+O39 -> 67.130174 | P42: =P35+P39 -> 70.240452 | ... S42: =S35+S39 -> 78.404533
D43: % margin | I43: =IF(ISERROR(I42/I$24),"n.a.",(I42/I$24)) -> 0.040892185 | J43: =IF(ISERROR(J42/J$24),"n.a.",(J42/J$24)) -> -0.024336271 | K43: =IF(ISERROR(K42/K$24),"n.a.",(K42/K$24)) -> 0.039605368 | L43: =IF(ISERROR(L42/L$24),"n.a.",(L42/L$24)) -> 0.041624257 | M43: =IF(ISERROR(M42/M$24),"n.a.",(M42/M$24)) -> 0.041866608 | N43: =IF(ISERROR(N42/N$24),"n.a.",(N42/N$24)) -> 0.043388457 | O43: =IF(ISERROR(O42/O$24),"n.a.",(O42/O$24)) -> 0.044814419 | P43: =IF(ISERROR(P42/P$24),"n.a.",(P42/P$24)) -> 0.046152325 | ... S43: =IF(ISERROR(S42/S$24),"n.a.",(S42/S$24)) -> 0.049705863
D44: % growth | I44: =IF(ISERROR(I42/H42-1),"n.a.",(I42/H42-1)) -> n.a. | J44: =IF(ISERROR(J42/I42-1),"n.a.",(J42/I42-1)) -> -1.569638 | K44: =IF(ISERROR(K42/J42-1),"n.a.",(K42/J42-1)) -> -3.0029672 | L44: =IF(ISERROR(L42/K42-1),"n.a.",(L42/K42-1)) -> 0.12327766 | M44: =IF(ISERROR(M42/L42-1),"n.a.",(M42/L42-1)) -> 0.002794993 | N44: =IF(ISERROR(N42/M42-1),"n.a.",(N42/M42-1)) -> 0.057076953 | O44: =IF(ISERROR(O42/N42-1),"n.a.",(O42/N42-1)) -> 0.051456568 | P44: =IF(ISERROR(P42/O42-1),"n.a.",(P42/O42-1)) -> 0.046332051 | ... S44: =IF(ISERROR(S42/R42-1),"n.a.",(S42/R42-1)) -> 0.033155504
D46: D&A | G46: ='Company fin forecasts'!C23 -> -51 | I46: =-I31 -> 36.129215 | J46: =-J31 -> 40.455294 | K46: =-K31 -> 47.195258 | L46: =-L31 -> 51.829544 | M46: =-M31 -> 54.799912 | N46: =-N31 -> 53.583371 | O46: =-O31 -> 52.366775 | P46: =-P31 -> 51.150123 | ... S46: =-S31 -> 47.5
D48: Capex | F48: =+' Financials'!I72 -> -36.1 | G48: =+' Financials'!J72 -> -37.3 | H48: =+' Financials'!K72 -> -31 | I48: =+' Financials'!L72 -> -36 | J48: =+' Financials'!M72 -> -51 | K48: =+' Financials'!N72 -> -50 | L48: =+' Financials'!O72 -> -50 | M48: =+' Financials'!P72 -> -50 | ... S48: =+' Financials'!V72 -> -50
D49: % sales | F49: =IF(ISERROR(-F48/F$24),"n.a.",(-F48/F$24)) -> 0.032968037 | G49: =IF(ISERROR(-G48/G$24),"n.a.",(-G48/G$24)) -> 0.032860541 | H49: =IF(ISERROR(-H48/H$24),"n.a.",(-H48/H$24)) -> 0.027226418 | I49: =IF(ISERROR(-I48/I$24),"n.a.",(-I48/I$24)) -> 0.031325289 | J49: =IF(ISERROR(-J48/J$24),"n.a.",(-J48/J$24)) -> 0.046363636 | K49: =IF(ISERROR(-K48/K$24),"n.a.",(-K48/K$24)) -> 0.036932057 | L49: =IF(ISERROR(-L48/L$24),"n.a.",(-L48/L$24)) -> 0.034554836 | M49: =IF(ISERROR(-M48/M$24),"n.a.",(-M48/M$24)) -> 0.034659154 | ... S49: =IF(ISERROR(-S48/S$24),"n.a.",(-S48/S$24)) -> 0.031698335
D50: % D&A | F50: =F48/F31 -> 1.1424051 | G50: ='Company fin forecasts'!C27 -> 16.111954 | H50: =H48/H31 -> 0.86111111 | I50: =I48/I31 -> 0.99642352 | J50: =J48/J31 -> 1.2606508 | K50: =K48/K31 -> 1.0594285 | L50: =L48/L31 -> 0.96470076 | M50: =M48/M31 -> 0.91241022 | N50: =N48/N31 -> 0.93312531 | O50: =O48/O31 -> 0.95480388 | ... S50: =S48/S31 -> 1.0526316
D52: Change in working capital | F52: =+' Financials'!I74 -> -16.3 | G52: =+' Financials'!J74 -> -12.6 | H52: =+' Financials'!K74 -> -10.4 | I52: =+' Financials'!L74 -> 6 | J52: =+' Financials'!M74 -> 16.111954 | K52: =+' Financials'!N74 -> 15.168893 | L52: =+' Financials'!O74 -> 11.110217 | M52: =+' Financials'!P74 -> 3.9548596 | ... S52: =+' Financials'!V74 -> 0
D53: % sales | F53: =IF(ISERROR(F52/F$24),"n.a.",(F52/F$24)) -> -0.014885845 | G53: ='Company fin forecasts'!C29 -> 0 | H53: =IF(ISERROR(H52/H$24),"n.a.",(H52/H$24)) -> -0.0091340242 | I53: =IF(ISERROR(I52/I$24),"n.a.",(I52/I$24)) -> 0.0052208815 | J53: =IF(ISERROR(J52/J$24),"n.a.",(J52/J$24)) -> 0.014647231 | K53: =IF(ISERROR(K52/K$24),"n.a.",(K52/K$24)) -> 0.011204368 | L53: =IF(ISERROR(L52/L$24),"n.a.",(L52/L$24)) -> 0.0076782344 | M53: =IF(ISERROR(M52/M$24),"n.a.",(M52/M$24)) -> 0.0027414417 | N53: =IF(ISERROR(N52/N$24),"n.a.",(N52/N$24)) -> 0 | O53: =IF(ISERROR(O52/O$24),"n.a.",(O52/O$24)) -> 0 | ... S53: =IF(ISERROR(S52/S$24),"n.a.",(S52/S$24)) -> 0
D55: Other Cashflows | F55: =+' Financials'!I76 -> 0 | G55: =+' Financials'!J76 -> -1.5 | H55: =+' Financials'!K76 -> 0.74 | I55: =+' Financials'!L76 -> 0 | J55: =+' Financials'!M76 -> 0 | K55: =+' Financials'!N76 -> -5 | L55: =+' Financials'!O76 -> -5 | M55: =+' Financials'!P76 -> -5 | ... S55: =+' Financials'!V76 -> -5
D56: % sales | F56: =IF(ISERROR(F55/F$24),"n.a.",(F55/F$24)) -> 0 | G56: ='Company fin forecasts'!C15 -> -18.004469 | H56: =IF(ISERROR(H55/H$24),"n.a.",(H55/H$24)) -> 0.00064992096 | I56: =IF(ISERROR(I55/I$24),"n.a.",(I55/I$24)) -> 0 | J56: =IF(ISERROR(J55/J$24),"n.a.",(J55/J$24)) -> 0 | K56: =IF(ISERROR(K55/K$24),"n.a.",(K55/K$24)) -> -0.0036932057 | L56: =IF(ISERROR(L55/L$24),"n.a.",(L55/L$24)) -> -0.0034554836 | M56: =IF(ISERROR(M55/M$24),"n.a.",(M55/M$24)) -> -0.0034659154 | N56: =IF(ISERROR(N55/N$24),"n.a.",(N55/N$24)) -> -0.0033979562 | O56: =IF(ISERROR(O55/O$24),"n.a.",(O55/O$24)) -> -0.0033378745 | ... S56: =IF(ISERROR(S55/S$24),"n.a.",(S55/S$24)) -> -0.0031698335
D58: Exceptional items | F58: =+' Financials'!I78 -> 0 | G58: =+' Financials'!J78 -> 0 | H58: =+' Financials'!K78 -> 0 | I58: =+' Financials'!L78 -> 0 | J58: =+' Financials'!M78 -> -18.004469 | K58: =+' Financials'!N78 -> -6.752718 | L58: =+' Financials'!O78 -> 25.138454 | M58: =+' Financials'!P78 -> -4.8650406 | ... S58: =+' Financials'!V78 -> 0
D59: % sales | F59: =IF(ISERROR(F58/F$24),"n.a.",(F58/F$24)) -> 0 | G59: =IF(ISERROR(G58/G$24),"n.a.",(G58/G$24)) -> 0 | H59: =IF(ISERROR(H58/H$24),"n.a.",(H58/H$24)) -> 0 | I59: =IF(ISERROR(I58/I$24),"n.a.",(I58/I$24)) -> 0 | J59: =IF(ISERROR(J58/J$24),"n.a.",(J58/J$24)) -> -0.016367699 | K59: =IF(ISERROR(K58/K$24),"n.a.",(K58/K$24)) -> -0.0049878354 | L59: =IF(ISERROR(L58/L$24),"n.a.",(L58/L$24)) -> 0.017373103 | M59: =IF(ISERROR(M58/M$24),"n.a.",(M58/M$24)) -> -0.0033723638 | ... S59: =IF(ISERROR(S58/S$24),"n.a.",(S58/S$24)) -> 0
D61: FCF | I61: =I42+I46+I48+I52+I55+I58 -> 53.123791 | J61: =J42+J46+J48+J52+J55+J58 -> -39.207119 | K61: =K42+K46+K48+K52+K55+K58 -> 54.230659 | L61: =L42+L46+L48+L52+L55+L58 -> 93.307494 | M61: =M42+M46+M48+M52+M55+M58 -> 59.287351 | N61: =N42+N46+N48+N52+N55+N58 -> 62.428304 | O61: =O42+O46+O48+O52+O55+O58 -> 64.496949 | P61: =P42+P46+P48+P52+P55+P58 -> 66.390575 | ... S61: =S42+S46+S48+S52+S55+S58 -> 70.904532
D63: Stub period | I63: =-I18*I61 -> -53.123791 | J63: =-J18*J61 -> 0.02683581 | K63: =-K18*K61 -> 0 | L63: =-L18*L61 -> 0 | M63: =-M18*M61 -> 0 | N63: =-N18*N61 -> 0 | O63: =-O18*O61 -> 0 | P63: =-P18*P61 -> 0 | ... S63: =-S18*S61 -> 0
...

Sheet DCF output
A1: DCF output
C5: Summary financials and cashflow
C7: DCF Forecast Year | I7: 0 | J7: =+I7+1 -> 1 | K7: =+J7+1 -> 2 | L7: =+K7+1 -> 3 | M7: =+L7+1 -> 4 | N7: =+M7+1 -> 5 | O7: =+N7+1 -> 6 | P7: =+O7+1 -> 7 | Q7: =+P7+1 -> 8 | ... S7: =+R7+1 -> 10 | T7: TV
C8: Mar YE ($m) | I8: =+'DCF input'!I22 -> 43921 | J8: =+'DCF input'!J22 -> 44286 | K8: =+'DCF input'!K22 -> 44651 | L8: =+'DCF input'!L22 -> 45016 | M8: =+'DCF input'!M22 -> 45382 | N8: =+'DCF input'!N22 -> 45747 | O8: =+'DCF input'!O22 -> 46112 | P8: =+'DCF input'!P22 -> 46477 | ... S8: =+'DCF input'!S22 -> 47573
C9: Revenue | I9: ='DCF input'!I24 -> 1149.2312 | J9: ='DCF input'!J24 -> 1100 | K9: ='DCF input'!K24 -> 1353.8374 | L9: ='DCF input'!L24 -> 1446.9755 | M9: ='DCF input'!M24 -> 1442.6203 | N9: ='DCF input'!N24 -> 1471.4728 | O9: ='DCF input'!O24 -> 1497.9593 | P9: ='DCF input'!P24 -> 1521.9266 | ... S9: ='DCF input'!S24 -> 1577.3699
C10: % growth | J10: =J9/I9-1 -> -0.042838389 | K10: =K9/J9-1 -> 0.23076126 | L10: =L9/K9-1 -> 0.068795629 | M10: =M9/L9-1 -> -0.0030098203 | N10: =N9/M9-1 -> 0.02 | O10: =O9/N9-1 -> 0.018000001 | P10: =P9/O9-1 -> 0.016000001 | Q10: =Q9/P9-1 -> 0.014000001 | ... S10: =S9/R9-1 -> 0.01
C11: EBITDA | I11: ='DCF input'!I27 -> 94.14721 | J11: ='DCF input'!J27 -> 8.2024043 | K11: ='DCF input'!K27 -> 111.79674 | L11: ='DCF input'!L27 -> 124.39494 | M11: ='DCF input'!M27 -> 127.56813 | N11: ='DCF input'!N27 -> 130.50498 | O11: ='DCF input'!O27 -> 133.2465 | P11: ='DCF input'!P27 -> 135.77717 | ... S11: ='DCF input'!S27 -> 141.96329
C12: % margin | I12: =I11/I9 -> 0.081921904 | J12: =J11/J9 -> 0.0074567312 | K12: =K11/K9 -> 0.08257767 | L12: =L11/L9 -> 0.085968935 | M12: =M11/M9 -> 0.088428068 | N12: =N11/N9 -> 0.08869004 | O12: =O11/O9 -> 0.08895202 | P12: =P11/P9 -> 0.089214009 | ... S12: =S11/S9 -> 0.09
C13: % growth | J13: =J11/I11-1 -> -0.91287682 | K13: =K11/J11-1 -> 12.629752 | L13: =L11/K11-1 -> 0.11268848 | M13: =M11/L11-1 -> 0.025508982 | N13: =N11/M11-1 -> 0.023021795 | O13: =O11/N11-1 -> 0.021007058 | P13: =P11/O11-1 -> 0.018992407 | Q13: =Q11/P11-1 -> 0.016977817 | ... S13: =S11/R11-1 -> 0.012948785
C14: D&A | I14: ='DCF input'!I31 -> -36.129215 | J14: ='DCF input'!J31 -> -40.455294 | K14: ='DCF input'!K31 -> -47.195258 | L14: ='DCF input'!L31 -> -51.829544 | M14: ='DCF input'!M31 -> -54.799912 | N14: ='DCF input'!N31 -> -53.583371 | O14: ='DCF input'!O31 -> -52.366775 | P14: ='DCF input'!P31 -> -51.150123 | ... S14: ='DCF input'!S31 -> -47.5
C15: % of revenue | I15: =-I14/I$9 -> 0.031437725 | J15: =-J14/J$9 -> 0.03677754 | K15: =-K14/K$9 -> 0.034860359 | L15: =-L14/L$9 -> 0.035819227 | M15: =-M14/M$9 -> 0.037986371 | N15: =-N14/N$9 -> 0.03641479 | O15: =-O14/O$9 -> 0.034958745 | P15: =-P14/P$9 -> 0.033608798 | ... S15: =-S14/S$9 -> 0.030113418
C16: % of capex | J16: =+J14/J21 -> 0.79324105 | K16: =+K14/K21 -> 0.94390515 | L16: =+L14/L21 -> 1.0365909 | M16: =+M14/M21 -> 1.0959982 | N16: =+N14/N21 -> 1.0716674 | O16: =+O14/O21 -> 1.0473355 | P16: =+P14/P21 -> 1.0230025 | Q16: =+Q14/Q21 -> 0.99866859 | ... S16: =+S14/S21 -> 0.95
C17: EBIT | I17: =I11+I14 -> 58.017994 | J17: =J11+J14 -> -32.252889 | K17: =K11+K14 -> 64.601479 | L17: =L11+L14 -> 72.565397 | M17: =M11+M14 -> 72.768217 | N17: =N11+N14 -> 76.921605 | O17: =O11+O14 -> 80.879727 | P17: =P11+P14 -> 84.627051 | ... S17: =S11+S14 -> 94.463292
C18: % margin | I18: =I17/I$9 -> 0.050484179 | J18: =J17/J$9 -> -0.029320808 | K18: =K17/K$9 -> 0.04771731 | L18: =L17/L$9 -> 0.050149708 | M18: =M17/M$9 -> 0.050441696 | N18: =N17/N$9 -> 0.05227525 | O18: =O17/O$9 -> 0.053993276 | P18: =P17/P$9 -> 0.055605211 | ... S18: =S17/S$9 -> 0.059886582
C19: Tax on EBIT | J19: =-J20*J17 -> 5.4829912 | K19: =-K20*K17 -> -10.982251 | L19: =-L20*L17 -> -12.336118 | M19: =-M20*M17 -> -12.370597 | N19: =-N20*N17 -> -13.076673 | O19: =-O20*O17 -> -13.749554 | P19: =-P20*P17 -> -14.386599 | Q19: =-Q20*Q17 -> -14.985321 | ... S19: =-S20*S17 -> -16.05876
C20: % tax rate | J20: ='DCF input'!J40 -> 0.17 | K20: ='DCF input'!K40 -> 0.17 | L20: ='DCF input'!L40 -> 0.17 | M20: ='DCF input'!M40 -> 0.17 | N20: ='DCF input'!N40 -> 0.17 | O20: ='DCF input'!O40 -> 0.17 | P20: ='DCF input'!P40 -> 0.17 | Q20: ='DCF input'!Q40 -> 0.17 | ... S20: ='DCF input'!S40 -> 0.17
C21: Capex | J21: ='DCF input'!J48 -> -51 | K21: ='DCF input'!K48 -> -50 | L21: ='DCF input'!L48 -> -50 | M21: ='DCF input'!M48 -> -50 | N21: ='DCF input'!N48 -> -50 | O21: ='DCF input'!O48 -> -50 | P21: ='DCF input'!P48 -> -50 | Q21: ='DCF input'!Q48 -> -50 | ... S21: ='DCF input'!S48 -> -50
C22: % of revenue | J22: =-J21/J$9 -> 0.046363636 | K22: =-K21/K$9 -> 0.036932057 | L22: =-L21/L$9 -> 0.034554836 | M22: =-M21/M$9 -> 0.034659154 | N22: =-N21/N$9 -> 0.033979562 | O22: =-O21/O$9 -> 0.033378745 | P22: =-P21/P$9 -> 0.032853095 | Q22: =-Q21/Q$9 -> 0.032399502 | ... S22: =-S21/S$9 -> 0.031698335
C23: Change in NWC | J23: ='DCF input'!J52 -> 16.111954 | K23: ='DCF input'!K52 -> 15.168893 | L23: ='DCF input'!L52 -> 11.110217 | M23: ='DCF input'!M52 -> 3.9548596 | N23: ='DCF input'!N52 -> 0 | O23: ='DCF input'!O52 -> 0 | P23: ='DCF input'!P52 -> 0 | Q23: ='DCF input'!Q52 -> 0 | ... S23: ='DCF input'!S52 -> 0
C24: Other Cashflows | J24: ='DCF input'!J55 -> 0 | K24: ='DCF input'!K55 -> -5 | L24: ='DCF input'!L55 -> -5 | M24: ='DCF input'!M55 -> -5 | N24: ='DCF input'!N55 -> -5 | O24: ='DCF input'!O55 -> -5 | P24: ='DCF input'!P55 -> -5 | Q24: ='DCF input'!Q55 -> -5 | ... S24: ='DCF input'!S55 -> -5
C25: % of revenue | J25: =-J24/J$9 -> 0 | K25: =-K24/K$9 -> 0.0036932057 | L25: =-L24/L$9 -> 0.0034554836 | M25: =-M24/M$9 -> 0.0034659154 | N25: =-N24/N$9 -> 0.0033979562 | O25: =-O24/O$9 -> 0.0033378745 | P25: =-P24/P$9 -> 0.0032853095 | Q25: =-Q24/Q$9 -> 0.0032399502 | ... S25: =-S24/S$9 -> 0.0031698335
C26: Exceptional items | J26: ='DCF input'!J58 -> -18.004469 | K26: ='DCF input'!K58 -> -6.752718 | L26: ='DCF input'!L58 -> 25.138454 | M26: ='DCF input'!M58 -> -4.8650406 | N26: ='DCF input'!N58 -> 0 | O26: ='DCF input'!O58 -> 0 | P26: ='DCF input'!P58 -> 0 | Q26: ='DCF input'!Q58 -> 0 | ... S26: ='DCF input'!S58 -> 0
C27: % of revenue | J27: =-J26/J$9 -> 0.016367699 | K27: =-K26/K$9 -> 0.0049878354 | L27: =-L26/L$9 -> -0.017373103 | M27: =-M26/M$9 -> 0.0033723638 | N27: =-N26/N$9 -> 0 | O27: =-O26/O$9 -> 0 | P27: =-P26/P$9 -> 0 | Q27: =-Q26/Q$9 -> 0 | ... S27: =-S26/S$9 -> 0
C28: Unlevered free cash flow | J28: =J17+J19-J14+J21+J23+J24+J26 -> -39.207119 | K28: =K17+K19-K14+K21+K23+K24+K26 -> 54.230659 | L28: =L17+L19-L14+L21+L23+L24+L26 -> 93.307494 | M28: =M17+M19-M14+M21+M23+M24+M26 -> 59.287351 | N28: =N17+N19-N14+N21+N23+N24+N26 -> 62.428304 | O28: =O17+O19-O14+O21+O23+O24+O26 -> 64.496949 | P28: =P17+P19-P14+P21+P23+P24+P26 -> 66.390575 | Q28: =Q17+Q19-Q14+Q21+Q23+Q24+Q26 -> 68.097054 | ... S28: =S17+S19-S14+S21+S23+S24+S26 -> 70.904532 | T28: =S28*(1+'DCF input'!F9)/('DCF input'!F11-'DCF input'!F9) -> 890.73819
C29: Cashflow Timing (Years to Discount) | J29: =J7 -> 1 | K29: =K7 -> 2 | L29: =L7 -> 3 | M29: =M7 -> 4 | N29: =N7 -> 5 | O29: =O7 -> 6 | P29: =P7 -> 7 | Q29: =Q7 -> 8 | ... S29: =S7 -> 10
C30: Discount Factor | J30: ='DCF input'!J67 -> 0.92165899 | K30: ='DCF input'!K67 -> 0.84945529 | L30: ='DCF input'!L67 -> 0.7829081 | M30: ='DCF input'!M67 -> 0.72157428 | N30: ='DCF input'!N67 -> 0.66504542 | O30: ='DCF input'!O67 -> 0.61294509 | P30: ='DCF input'!P67 -> 0.56492635 | Q30: ='DCF input'!Q67 -> 0.52066945 | ... S30: ='DCF input'!S67 -> 0.44228542
C31: Discounted DCF cashflows | J31: =J30*J28 -> -36.135593 | K31: =K30*K28 -> 46.06652 | L31: =L30*L28 -> 73.051193 | M31: =M30*M28 -> 42.780228 | N31: =N30*N28 -> 41.517658 | O31: =O30*O28 -> 39.533088 | P31: =P30*P28 -> 37.505786 | Q31: =Q30*Q28 -> 35.456055 | ... S31: =S30*S28 -> 31.360041 | T31: =T28*S30 -> 393.96051
C33: Net Present Value based on Perpetuity Growth Method
C35: ="Value Based on "&TEXT(K40,"#0.0%")&" WACC & "&TEXT(N37,"#0.0%")&" TGR" -> Value Based on 8.5% WACC & 0.5% TGR | F35: Amount | G35: % of | J35: Sensitising firm value ($m) and implied offer price to WACC and TGR
F36: ($m) | G36: NPV | L36: Perpetuity Growth Rate (%)
C37: Present Value of Cashflows | F37: =SUM(J31:S31) -> 344.53706 | G37: =F37/F$39 -> 0.46653784 | J37: WACC (%) | L37: ='DCF input'!F103 -> 0 | M37: ='DCF input'!G103 -> 0.0025 | N37: ='DCF input'!H103 -> 0.005 | O37: ='DCF input'!I103 -> 0.0075 | P37: ='DCF input'!J103 -> 0.01
C38: PV of Terminal Value | F38: =T31 -> 393.96051 | G38: =F38/F$39 -> 0.53346216 | K38: ='DCF input'!E95 -> 0.075 | L38: =CONCATENATE(ROUND('DCF input'!F95,)," / ",ROUND('DCF input'!F104,0),"c") -> 0 / -43c | M38: =CONCATENATE(ROUND('DCF input'!G95,)," / ",ROUND('DCF input'!G104,0),"c") -> #VALUE! | N38: =CONCATENATE(ROUND('DCF input'!H95,)," / ",ROUND('DCF input'!H104,0),"c") -> #VALUE! | O38: =CONCATENATE(ROUND('DCF input'!I95,)," / ",ROUND('DCF input'!I104,0),"c") -> #VALUE! | P38: =CONCATENATE(ROUND('DCF input'!J95,)," / ",ROUND('DCF input'!J104,0),"c") -> #VALUE!
C39: Implied Firm NPV | F39: =(F38+F37) -> 738.49757 | G39: =F39/F$39 -> 1 | K39: ='DCF input'!E96 -> 0.08 | L39: =CONCATENATE(ROUND('DCF input'!F96,)," / ",ROUND('DCF input'!F105,0),"c") -> #VALUE! | M39: =CONCATENATE(ROUND('DCF input'!G96,)," / ",ROUND('DCF input'!G105,0),"c") -> #VALUE! | N39: =CONCATENATE(ROUND('DCF input'!H96,)," / ",ROUND('DCF input'!H105,0),"c") -> #VALUE! | O39: =CONCATENATE(ROUND('DCF input'!I96,)," / ",ROUND('DCF input'!I105,0),"c") -> #VALUE! | P39: =CONCATENATE(ROUND('DCF input'!J96,)," / ",ROUND('DCF input'!J105,0),"c") -> #VALUE!
C40: Net debt & adjustments | F40: =+'DCF input'!H78 -> -84.616814 | K40: ='DCF input'!E97 -> 0.085 | L40: =CONCATENATE(ROUND('DCF input'!F97,)," / ",ROUND('DCF input'!F106,0),"c") -> #VALUE! | M40: =CONCATENATE(ROUND('DCF input'!G97,)," / ",ROUND('DCF input'!G106,0),"c") -> #VALUE! | N40: =CONCATENATE(ROUND('DCF input'!H97,)," / ",ROUND('DCF input'!H106,0),"c") -> #VALUE! | O40: =CONCATENATE(ROUND('DCF input'!I97,)," / ",ROUND('DCF input'!I106,0),"c") -> #VALUE! | P40: =CONCATENATE(ROUND('DCF input'!J97,)," / ",ROUND('DCF input'!J106,0),"c") -> #VALUE!
C41: Implied equity value | F41: =+F39+F40 -> 653.88076 | K41: ='DCF input'!E98 -> 0.09 | L41: =CONCATENATE(ROUND('DCF input'!F98,)," / ",ROUND('DCF input'!F107,0),"c") -> #VALUE! | M41: =CONCATENATE(ROUND('DCF input'!G98,)," / ",ROUND('DCF input'!G107,0),"c") -> #VALUE! | N41: =CONCATENATE(ROUND('DCF input'!H98,)," / ",ROUND('DCF input'!H107,0),"c") -> #VALUE! | O41: =CONCATENATE(ROUND('DCF input'!I98,)," / ",ROUND('DCF input'!I107,0),"c") -> #VALUE! | P41: =CONCATENATE(ROUND('DCF input'!J98,)," / ",ROUND('DCF input'!J107,0),"c") -> #VALUE!
C42: Implied share price ($c) | F42: =+F41/Assumptions!D17*100 -> 328.5833 | K42: ='DCF input'!E99 -> 0.095 | L42: =CONCATENATE(ROUND('DCF input'!F99,)," / ",ROUND('DCF input'!F108,0),"c") -> #VALUE! | M42: =CONCATENATE(ROUND('DCF input'!G99,)," / ",ROUND('DCF input'!G108,0),"c") -> #VALUE! | N42: =CONCATENATE(ROUND('DCF input'!H99,)," / ",ROUND('DCF input'!H108,0),"c") -> #VALUE! | O42: =CONCATENATE(ROUND('DCF input'!I99,)," / ",ROUND('DCF input'!I108,0),"c") -> #VALUE! | P42: =CONCATENATE(ROUND('DCF input'!J99,)," / ",ROUND('DCF input'!J108,0),"c") -> #VALUE!
C43: % premium to current | F43: =+F42/Assumptions!D16-1 -> 0.99141391
